Starting D10 Discord bot...

Checking and installing required packages...
Requirement already satisfied: discord.py in c:\users\huber\appdata\local\programs\python\python312\lib\site-packages (2.5.2)
Requirement already satisfied: python-dotenv in c:\users\huber\appdata\local\programs\python\python312\lib\site-packages (1.1.0)
Requirement already satisfied: asyncio in c:\users\huber\appdata\local\programs\python\python312\lib\site-packages (3.4.3)
Requirement already satisfied: aiohttp in c:\users\huber\appdata\local\programs\python\python312\lib\site-packages (3.11.17)
Requirement already satisfied: aiohappyeyeballs>=2.3.0 in c:\users\huber\appdata\local\programs\python\python312\lib\site-packages (from aiohttp) (2.6.1)
Requirement already satisfied: aiosignal>=1.1.2 in c:\users\huber\appdata\local\programs\python\python312\lib\site-packages (from aiohttp) (1.3.2)
Requirement already satisfied: attrs>=17.3.0 in c:\users\huber\appdata\local\programs\python\python312\lib\site-packages (from aiohttp) (25.3.0)
Requirement already satisfied: frozenlist>=1.1.1 in c:\users\huber\appdata\local\programs\python\python312\lib\site-packages (from aiohttp) (1.5.0)
Requirement already satisfied: multidict<7.0,>=4.5 in c:\users\huber\appdata\local\programs\python\python312\lib\site-packages (from aiohttp) (6.1.0)
Requirement already satisfied: propcache>=0.2.0 in c:\users\huber\appdata\local\programs\python\python312\lib\site-packages (from aiohttp) (0.3.0)
Requirement already satisfied: yarl<2.0,>=1.17.0 in c:\users\huber\appdata\local\programs\python\python312\lib\site-packages (from aiohttp) (1.18.3)
Requirement already satisfied: idna>=2.0 in c:\users\huber\appdata\local\programs\python\python312\lib\site-packages (from yarl<2.0,>=1.17.0->aiohttp) (2.10)

[notice] A new release of pip is available: 24.3.1 -> 25.0.1
[notice] To update, run: python.exe -m pip install --upgrade pip

Starting the bot...
(Press Ctrl+C to stop the bot)

2025-04-20 03:54:01,664 - discord.client - WARNING - PyNaCl is not installed, voice will NOT be supported
 * Serving Flask app 'main'
 * Debug mode: off
2025-04-20 03:54:01,684 - werkzeug - INFO - WARNING: This is a development server. Do not use it in a production deployment. Use a production WSGI server instead.
 * Running on all addresses (0.0.0.0)
 * Running on http://127.0.0.1:8080
 * Running on http://192.168.86.106:8080
2025-04-20 03:54:01,684 - werkzeug - INFO - Press CTRL+C to quit
2025-04-20 03:54:05,703 - d10-bot - ERROR - Database connection error: connection to server at "localhost" (::1), port 5432 failed: Connection refused (0x0000274D/10061)
        Is the server running on that host and accepting TCP/IP connections?
connection to server at "localhost" (127.0.0.1), port 5432 failed: Connection refused (0x0000274D/10061)
        Is the server running on that host and accepting TCP/IP connections?

2025-04-20 03:54:05,704 - d10-bot - ERROR - Database setup error: connection to server at "localhost" (::1), port 5432 failed: Connection refused (0x0000274D/10061)
        Is the server running on that host and accepting TCP/IP connections?
connection to server at "localhost" (127.0.0.1), port 5432 failed: Connection refused (0x0000274D/10061)
        Is the server running on that host and accepting TCP/IP connections?

Exception in thread Thread-1 (run_discord_bot):
Traceback (most recent call last):
  File "C:\Users\huber\AppData\Local\Programs\Python\Python312\Lib\threading.py", line 1075, in _bootstrap_inner
    self.run()
  File "C:\Users\huber\AppData\Local\Programs\Python\Python312\Lib\threading.py", line 1012, in run
    self._target(*self._args, **self._kwargs)
  File "D:\Downloads\DiscordCompanions-main\DiscordCompanions-main\main.py", line 124, in run_discord_bot
    bot = D10Bot()
          ^^^^^^^^
  File "D:\Downloads\DiscordCompanions-main\DiscordCompanions-main\bot.py", line 35, in __init__
    self.db = Database()
              ^^^^^^^^^^
  File "D:\Downloads\DiscordCompanions-main\DiscordCompanions-main\database.py", line 23, in __init__
    self._setup_database()
  File "D:\Downloads\DiscordCompanions-main\DiscordCompanions-main\database.py", line 59, in _setup_database
    with self._connect() as conn:
         ^^^^^^^^^^^^^^^
  File "D:\Downloads\DiscordCompanions-main\DiscordCompanions-main\database.py", line 49, in _connect
    return psycopg2.connect(**self.connection_params)
           ^^^^^^^^^^^^^^^^^^^^^^^^^^^^^^^^^^^^^^^^^^
  File "C:\Users\huber\AppData\Local\Programs\Python\Python312\Lib\site-packages\psycopg2\__init__.py", line 122, in connect
    conn = _connect(dsn, connection_factory=connection_factory, **kwasync)
           ^^^^^^^^^^^^^^^^^^^^^^^^^^^^^^^^^^^^^^^^^^^^^^^^^^^^^^^^^^^^^^^
psycopg2.OperationalError: connection to server at "localhost" (::1), port 5432 failed: Connection refused (0x0000274D/10061)
        Is the server running on that host and accepting TCP/IP connections?
connection to server at "localhost" (127.0.0.1), port 5432 failed: Connection refused (0x0000274D/10061)
        Is the server running on that host and accepting TCP/IP connections?